<?xml version="1.0" encoding="utf-8"?>
<!-- This URDF was automatically created by SolidWorks to URDF Exporter! Originally created by Stephen Brawner (brawner@gmail.com) 
     Commit Version: 1.6.0-4-g7f85cfe  Build Version: 1.6.7995.38578
     For more information, please see http://wiki.ros.org/sw_urdf_exporter -->
<robot
  name="TOE_dog">
  <link
    name="base">
    <inertial>
      <origin
        xyz="-0.0032287234218103 7.70734400253109E-05 -0.00141709330891995"
        rpy="0 0 0" />
      <mass
        value="4.54798558136244" />
      <inertia
        ixx="0.00613493898973863"
        ixy="-4.41014715233488E-06"
        ixz="1.32276153739254E-06"
        iyy="0.00509417573470022"
        iyz="1.30702407567351E-05"
        izz="0.00671110624937603" />
    </inertial>
    <visual>
      <origin
        xyz="0 0 0"
        rpy="0 0 0" />
      <geometry>
        <mesh
          filename="package://urdf_tutorial/meshes/TOE_base.STL" />
      </geometry>
      <material
        name="">
        <color
          rgba="0.752941176470588 0.752941176470588 0.752941176470588 1" />
      </material>
    </visual>
    <collision>
      <origin
        xyz="0 0 0"
        rpy="0 0 0" />
      <geometry>
        <box size="0.27 0.0146 0.034"/>
      </geometry>
    </collision>
  </link>
  <link
    name="FL_hip">
    <inertial>
      <origin
        xyz="-0.000462628009896944 0.00296787906267088 -0.000377200721687631"
        rpy="0 0 0" />
      <mass
        value="0.629531151087716" />
      <inertia
        ixx="0.00051570161163585"
        ixy="4.06707920917839E-06"
        ixz="3.3371017718684E-06"
        iyy="0.000756722047976196"
        iyz="-5.39904498541625E-06"
        izz="0.000529259319541234" />
    </inertial>
    <visual>
      <origin
        xyz="0 0 0"
        rpy="0 0 0" />
      <geometry>
        <mesh
          filename="package://urdf_tutorial/meshes/TOE_FL_hip.STL" />
      </geometry>
      <material
        name="">
        <color
          rgba="0.752941176470588 0.752941176470588 0.752941176470588 1" />
      </material>
    </visual>
    <collision>
      <origin
        xyz="0 0.05 0"
        rpy="1.5708 0 0" />
      <geometry>
        <cylinder length="0.08" radius="0.046" />
      </geometry>
    </collision>
  </link>
  <joint
    name="FL_hip_joint"
    type="revolute">
    <origin
      xyz="0.2 0.05 0"
      rpy="0 0 0" />
    <parent
      link="base" />
    <child
      link="FL_hip" />
    <axis
      xyz="1 0 0" />
    <limit
      lower="-3.14"
      upper="3.14"
      effort="100"
      velocity="100" />
  </joint>
  <link
    name="FL_thigh">
    <inertial>
      <origin
        xyz="0.00026725027155268 -0.0225192600801335 -0.0253114510050126"
        rpy="0 0 0" />
      <mass
        value="1.03325516874254" />
      <inertia
        ixx="0.00148857519015616"
        ixy="8.84694951062226E-06"
        ixz="1.39246968935862E-06"
        iyy="0.00182877264158558"
        iyz="-3.85683945171664E-06"
        izz="0.000635560794570049" />
    </inertial>
    <visual>
      <origin
        xyz="0 0 0"
        rpy="0 0 0" />
      <geometry>
        <mesh
          filename="package://urdf_tutorial/meshes/TOE_thigh.STL" />
      </geometry>
      <material
        name="">
        <color
          rgba="0.752941176470588 0.752941176470588 0.752941176470588 1" />
      </material>
    </visual>
    <collision>
      <origin rpy="0 1.5707963267948966 0" xyz="0 0 -0.11" />
      <geometry>
        <box size="0.11 0.0245 0.04" />
      </geometry>
    </collision>
  </link>
  <joint
    name="FL_thigh_joint"
    type="revolute">
    <origin
      xyz="0 0.08953 0"
      rpy="0 0 0" />
    <parent
      link="FL_hip" />
    <child
      link="FL_thigh" />
    <axis
      xyz="0 1 0" />
    <limit
      lower="-3.14"
      upper="3.14"
      effort="100"
      velocity="100" />
  </joint>
  <link
    name="FL_calf">
    <inertial>
      <origin
        xyz="0.00144797029171106 -1.62071723394386E-05 -0.0632711754855739"
        rpy="0 0 0" />
      <mass
        value="1.00739173378192" />
      <inertia
        ixx="0.00372396847961745"
        ixy="2.67412757088564E-08"
        ixz="0.000158148920550335"
        iyy="0.00378909465166996"
        iyz="7.31395566676369E-07"
        izz="0.00016917553145981" />
    </inertial>
    <visual>
      <origin
        xyz="0 0 0"
        rpy="0 0 0" />
      <geometry>
        <mesh
          filename="package://urdf_tutorial/meshes/TOE_calf.STL" />
      </geometry>
      <material
        name="">
        <color
          rgba="0.752941176470588 0.752941176470588 0.752941176470588 1" />
      </material>
    </visual>
    <collision>
      <origin rpy="0 1.5708 0" xyz="0 0 -0.09" />
      <geometry>
        <box size="0.16 0.0245 0.04" />
      </geometry>
    </collision>
  </link>
  <joint
    name="FL_calf_joint"
    type="revolute">
    <origin
      xyz="0 0 -0.18"
      rpy="0 0 0" />
    <parent
      link="FL_thigh" />
    <child
      link="FL_calf" />
    <axis
      xyz="0 1 0" />
    <limit
      lower="-3.14"
      upper="3.14"
      effort="100"
      velocity="100" />
  </joint>
  <link
    name="FL_foot">
    <inertial>
      <origin
        xyz="-0.00557718053910585 -3.98315304828145E-06 -0.00961668940835148"
        rpy="0 0 0" />
      <mass
        value="0.0321912008369509" />
      <inertia
        ixx="5.28624515567063E-06"
        ixy="-1.62866342159991E-09"
        ixz="1.03446978648752E-06"
        iyy="5.18865524900234E-06"
        iyz="-6.35829799409648E-10"
        izz="6.57028618685068E-06" />
    </inertial>
    <visual>
      <origin
        xyz="0 0 0"
        rpy="0 0 0" />
      <geometry>
        <mesh
          filename="package://urdf_tutorial/meshes/TOE_foot.STL" />
      </geometry>
      <material
        name="">
        <color
          rgba="1 1 1 1" />
      </material>
    </visual>
    <collision>
      <origin
        xyz="0 0 0"
        rpy="0 0 0" />
      <geometry>
        <sphere radius="0.022" />
      </geometry>
    </collision>
  </link>
  <joint
    name="FL_foot_joint"
    type="fixed">
    <origin
      xyz="0.00081567 0 -0.20051"
      rpy="0 -0.0012583 0" />
    <parent
      link="FL_calf" />
    <child
      link="FL_foot" />
    <axis
      xyz="0 0 0" />
  </joint>
  <link
    name="FR_hip">
    <inertial>
      <origin
        xyz="-0.000462628009896923 -0.00296787906267089 0.000377200721687548"
        rpy="0 0 0" />
      <mass
        value="0.629531151087713" />
      <inertia
        ixx="0.000515701611635849"
        ixy="-4.06707920917812E-06"
        ixz="-3.3371017718681E-06"
        iyy="0.000756722047976193"
        iyz="-5.39904498541588E-06"
        izz="0.000529259319541232" />
    </inertial>
    <visual>
      <origin
        xyz="0 0 0"
        rpy="0 0 0" />
      <geometry>
        <mesh
          filename="package://urdf_tutorial/meshes/TOE_FR_hip.STL" />
      </geometry>
      <material
        name="">
        <color
          rgba="0.752941176470588 0.752941176470588 0.752941176470588 1" />
      </material>
    </visual>
    <collision>
      <origin rpy="1.5707963267948966 0 0" xyz="0 -0.05 0" />
      <geometry>
        <cylinder length="0.08" radius="0.046" />
      </geometry>
    </collision>
  </link>
  <joint
    name="FR_hip_joint"
    type="revolute">
    <origin
      xyz="0.2 -0.05 0"
      rpy="0 0 0" />
    <parent
      link="base" />
    <child
      link="FR_hip" />
    <axis
      xyz="1 0 0" />
    <limit
      lower="-3.14"
      upper="3.14"
      effort="100"
      velocity="100" />
  </joint>
  <link
    name="FR_thigh">
    <inertial>
      <origin
        xyz="-0.00052911 0.022389 -0.026316"
        rpy="0 0 0" />
      <mass
        value="1.0439" />
      <inertia
        ixx="0.0014882"
        ixy="9.0263E-06"
        ixz="4.4999E-08"
        iyy="0.0018303"
        iyz="-9.2698E-07"
        izz="0.00063661" />
    </inertial>
    <visual>
      <origin
        xyz="0 0 0"
        rpy="0 0 0" />
      <geometry>
        <mesh
          filename="package://urdf_tutorial/meshes/TOE_R_thigh.STL" />
      </geometry>
      <material
        name="">
        <color
          rgba="0.75294 0.75294 0.75294 1" />
      </material>
    </visual>
    <collision>
      <origin rpy="0 1.5707963267948966 0" xyz="0 0 -0.11" />
      <geometry>
        <box size="0.11 0.0245 0.04" />
      </geometry>
    </collision>
  </link>
  <joint
    name="FR_thigh_joint"
    type="revolute">
    <origin
      xyz="0 -0.08953 0"
      rpy="0 0 0" />
    <parent
      link="FR_hip" />
    <child
      link="FR_thigh" />
    <axis
      xyz="0 1 0" />
    <limit
      lower="-3.14"
      upper="3.14"
      effort="100"
      velocity="100" />
  </joint>
  <link
    name="FR_calf">
    <inertial>
      <origin
        xyz="0.001447973557225 -1.62084641121552E-05 -0.0632711777197613"
        rpy="0 0 0" />
      <mass
        value="1.00739190692492" />
      <inertia
        ixx="0.00372396847520427"
        ixy="2.67731382321561E-08"
        ixz="0.000158148892236574"
        iyy="0.00378909458476439"
        iyz="7.31380760289505E-07"
        izz="0.000169175488169915" />
    </inertial>
    <visual>
      <origin
        xyz="0 0 0"
        rpy="0 0 0" />
      <geometry>
        <mesh
          filename="package://urdf_tutorial/meshes/TOE_calf.STL" />
      </geometry>
      <material
        name="">
        <color
          rgba="0.752941176470588 0.752941176470588 0.752941176470588 1" />
      </material>
    </visual>
    <collision>
      <origin rpy="0 1.5708 0" xyz="0 0 -0.09" />
      <geometry>
        <box size="0.16 0.0245 0.04" />
      </geometry>
    </collision>
  </link>
  <joint
    name="FR_calf_joint"
    type="revolute">
    <origin
      xyz="0 0 -0.18"
      rpy="0 0 0" />
    <parent
      link="FR_thigh" />
    <child
      link="FR_calf" />
    <axis
      xyz="0 1 0" />
    <limit
      lower="-3.14"
      upper="3.14"
      effort="100"
      velocity="100" />
  </joint>
  <link
    name="FR_foot">
    <inertial>
      <origin
        xyz="-0.0055772 -3.9832E-06 -0.0096167"
        rpy="0 0 0" />
      <mass
        value="0.032191" />
      <inertia
        ixx="5.2862E-06"
        ixy="-1.6287E-09"
        ixz="1.0345E-06"
        iyy="5.1887E-06"
        iyz="-6.3583E-10"
        izz="6.5703E-06" />
    </inertial>
    <visual>
      <origin
        xyz="0 0 0"
        rpy="0 0 0" />
      <geometry>
        <mesh
          filename="package://urdf_tutorial/meshes/TOE_foot.STL" />
      </geometry>
      <material
        name="">
        <color
          rgba="1 1 1 1" />
      </material>
    </visual>
    <collision>
      <origin
        xyz="0 0 0"
        rpy="0 0 0" />
      <geometry>
        <sphere radius="0.022" />
      </geometry>
    </collision>
  </link>
  <joint
    name="FR_foot_joint"
    type="fixed">
    <origin
      xyz="0.00081567 0 -0.20051"
      rpy="0 -0.0012583 0" />
    <parent
      link="FR_calf" />
    <child
      link="FR_foot" />
    <axis
      xyz="0 0 0" />
  </joint>
    <link
    name="RL_hip">
    <inertial>
      <origin
        xyz="0.00046262797964941 0.00296787909188655 0.000377200771965971"
        rpy="0 0 0" />
      <mass
        value="0.629531150162588" />
      <inertia
        ixx="0.000515701610603418"
        ixy="-4.06707954630116E-06"
        ixz="3.33710318711867E-06"
        iyy="0.000756722046839394"
        iyz="5.39904558189335E-06"
        izz="0.00052925931870631" />
    </inertial>
    <visual>
      <origin
        xyz="0 0 0"
        rpy="0 0 0" />
      <geometry>
        <mesh
          filename="package://urdf_tutorial/meshes/TOE_RL_hip.STL" />
      </geometry>
      <material
        name="">
        <color
          rgba="0.752941176470588 0.752941176470588 0.752941176470588 1" />
      </material>
    </visual>
    <collision>
      <origin rpy="1.5707963267948966 0 0" xyz="0 0.05 0" />
      <geometry>
        <cylinder length="0.08" radius="0.046" />
      </geometry>
    </collision>
  </link>
  <joint
    name="RL_hip_joint"
    type="revolute">
    <origin
      xyz="-0.2 0.05 0"
      rpy="0 0 0" />
    <parent
      link="base" />
    <child
      link="RL_hip" />
    <axis
      xyz="1 0 0" />
    <limit
      lower="-3.14"
      upper="3.14"
      effort="100"
      velocity="100" />
  </joint>
  <link
    name="RL_thigh">
    <inertial>
      <origin
        xyz="0.00026725025835711 -0.0225192600682941 -0.0253114510097742"
        rpy="0 0 0" />
      <mass
        value="1.03325516817891" />
      <inertia
        ixx="0.00148857518931491"
        ixy="8.84694922236256E-06"
        ixz="1.39246901901229E-06"
        iyy="0.00182877264081886"
        iyz="-3.85683931677538E-06"
        izz="0.000635560794264501" />
    </inertial>
    <visual>
      <origin
        xyz="0 0 0"
        rpy="0 0 0" />
      <geometry>
        <mesh
          filename="package://urdf_tutorial/meshes/TOE_thigh.STL" />
      </geometry>
      <material
        name="">
        <color
          rgba="0.752941176470588 0.752941176470588 0.752941176470588 1" />
      </material>
    </visual>
    <collision>
      <origin rpy="0 1.5707963267948966 0" xyz="0 0 -0.11" />
      <geometry>
        <box size="0.11 0.0245 0.04" />
      </geometry>
    </collision>
  </link>
  <joint
    name="RL_thigh_joint"
    type="revolute">
    <origin
      xyz="0 0.08953 0"
      rpy="0 0 0" />
    <parent
      link="RL_hip" />
    <child
      link="RL_thigh" />
    <axis
      xyz="0 1 0" />
    <limit
      lower="-3.14"
      upper="3.14"
      effort="100"
      velocity="100" />
  </joint>
  <link
    name="RL_calf">
    <inertial>
      <origin
        xyz="0.00144797036282751 -1.62075761347136E-05 -0.0632711864020849"
        rpy="0 0 0" />
      <mass
        value="1.00739181390086" />
      <inertia
        ixx="0.00372396940501077"
        ixy="2.67653871683659E-08"
        ixz="0.000158148781945404"
        iyy="0.00378909544334424"
        iyz="7.31362662074009E-07"
        izz="0.000169175412937519" />
    </inertial>
    <visual>
      <origin
        xyz="0 0 0"
        rpy="0 0 0" />
      <geometry>
        <mesh
          filename="package://urdf_tutorial/meshes/TOE_calf.STL" />
      </geometry>
      <material
        name="">
        <color
          rgba="0.752941176470588 0.752941176470588 0.752941176470588 1" />
      </material>
    </visual>
    <collision>
      <origin rpy="0 1.5708 0" xyz="0 0 -0.09" />
      <geometry>
        <box size="0.16 0.0245 0.04" />
      </geometry>
    </collision>
  </link>
  <joint
    name="RL_calf_joint"
    type="revolute">
    <origin
      xyz="0 0 -0.18"
      rpy="0 0 0" />
    <parent
      link="RL_thigh" />
    <child
      link="RL_calf" />
    <axis
      xyz="0 1 0" />
    <limit
      lower="-3.14"
      upper="3.14"
      effort="100"
      velocity="100" />
  </joint>
  <link
    name="RL_foot">
    <inertial>
      <origin
        xyz="-0.00557718053910572 -3.98315304828145E-06 -0.00961668940835148"
        rpy="0 0 0" />
      <mass
        value="0.0321912008369509" />
      <inertia
        ixx="5.28624515567062E-06"
        ixy="-1.62866342160025E-09"
        ixz="1.03446978648754E-06"
        iyy="5.1886552490024E-06"
        iyz="-6.35829799416328E-10"
        izz="6.57028618685073E-06" />
    </inertial>
    <visual>
      <origin
        xyz="0 0 0"
        rpy="0 0 0" />
      <geometry>
        <mesh
          filename="package://urdf_tutorial/meshes/TOE_foot.STL" />
      </geometry>
      <material
        name="">
        <color
          rgba="1 1 1 1" />
      </material>
    </visual>
    <collision>
      <origin
        xyz="0 0 0"
        rpy="0 0 0" />
      <geometry>
        <sphere radius="0.022" />
      </geometry>
    </collision>
  </link>
  <joint
    name="RL_foot_joint"
    type="fixed">
    <origin
      xyz="0.00081567 0 -0.20051"
      rpy="0 -0.0012583 0" />
    <parent
      link="RL_calf" />
    <child
      link="RL_foot" />
    <axis
      xyz="0 0 0" />
  </joint>
  <link
    name="RR_hip">
    <inertial>
      <origin
        xyz="0.000462627948810912 -0.00296787907848253 -0.000377200749208193"
        rpy="0 0 0" />
      <mass
        value="0.629531150629571" />
      <inertia
        ixx="0.000515701611282"
        ixy="4.0670799167658E-06"
        ixz="-3.33710274625981E-06"
        iyy="0.000756722047444843"
        iyz="5.39904531575905E-06"
        izz="0.000529259318938924" />
    </inertial>
    <visual>
      <origin
        xyz="0 0 0"
        rpy="0 0 0" />
      <geometry>
        <mesh
          filename="package://urdf_tutorial/meshes/TOE_RR_hip.STL" />
      </geometry>
      <material
        name="">
        <color
          rgba="0.752941176470588 0.752941176470588 0.752941176470588 1" />
      </material>
    </visual>
    <collision>
      <origin rpy="1.5707963267948966 0 0" xyz="0 -0.05 0" />
      <geometry>
        <cylinder length="0.08" radius="0.046" />
      </geometry>
    </collision>
  </link>
  <joint
    name="RR_hip_joint"
    type="revolute">
    <origin
      xyz="-0.2 -0.05 0"
      rpy="0 0 0" />
    <parent
      link="base" />
    <child
      link="RR_hip" />
    <axis
      xyz="1 0 0" />
    <limit
      lower="-3.14"
      upper="3.14"
      effort="100"
      velocity="100" />
  </joint>
  <link
    name="RR_thigh">
    <inertial>
      <origin
        xyz="-0.000529112929206821 0.0223886518464307 -0.026316165403537"
        rpy="0 0 0" />
      <mass
        value="1.04394065787434" />
      <inertia
        ixx="0.00148820954378036"
        ixy="9.02633465512755E-06"
        ixz="4.49995103540568E-08"
        iyy="0.00183026511099994"
        iyz="-9.26979860955464E-07"
        izz="0.000636611592360065" />
    </inertial>
    <visual>
      <origin
        xyz="0 0 0"
        rpy="0 0 0" />
      <geometry>
        <mesh
          filename="package://urdf_tutorial/meshes/TOE_R_thigh.STL" />
      </geometry>
      <material
        name="">
        <color
          rgba="0.752941176470588 0.752941176470588 0.752941176470588 1" />
      </material>
    </visual>
    <collision>
      <origin rpy="0 1.5707963267948966 0" xyz="0 0 -0.11" />
      <geometry>
        <box size="0.11 0.0245 0.04" />
      </geometry>
    </collision>
  </link>
  <joint
    name="RR_thigh"
    type="revolute">
    <origin
      xyz="0 -0.08953 0"
      rpy="0 0 0" />
    <parent
      link="RR_hip" />
    <child
      link="RR_thigh" />
    <axis
      xyz="0 1 0" />
    <limit
      lower="-3.14"
      upper="3.14"
      effort="100"
      velocity="100" />
  </joint>
  <link
    name="RR_calf">
    <inertial>
      <origin
        xyz="0.00144796967229593 -1.62073079078007E-05 -0.0632711656523452"
        rpy="0 0 0" />
      <mass
        value="1.0073921841326" />
      <inertia
        ixx="0.00372397074451231"
        ixy="2.67657813561661E-08"
        ixz="0.00015814882139217"
        iyy="0.00378909678372777"
        iyz="7.31346458312211E-07"
        izz="0.000169175414001898" />
    </inertial>
    <visual>
      <origin
        xyz="0 0 0"
        rpy="0 0 0" />
      <geometry>
        <mesh
          filename="package://urdf_tutorial/meshes/TOE_calf.STL" />
      </geometry>
      <material
        name="">
        <color
          rgba="0.752941176470588 0.752941176470588 0.752941176470588 1" />
      </material>
    </visual>
    <collision>
      <origin rpy="0 1.5708 0" xyz="0 0 -0.09" />
      <geometry>
        <box size="0.16 0.0245 0.04" />
      </geometry>
    </collision>
  </link>
  <joint
    name="RR_calf_joint"
    type="revolute">
    <origin
      xyz="0 0 -0.18"
      rpy="0 0 0" />
    <parent
      link="RR_thigh" />
    <child
      link="RR_calf" />
    <axis
      xyz="0 1 0" />
    <limit
      lower="-3.14"
      upper="3.14"
      effort="100"
      velocity="100" />
  </joint>
  <link
    name="RR_foot">
    <inertial>
      <origin
        xyz="-0.00557718054766365 -3.98323834327474E-06 -0.00961668941940308"
        rpy="0 0 0" />
      <mass
        value="0.0321912006524897" />
      <inertia
        ixx="5.28624511121923E-06"
        ixy="-1.62865946758586E-09"
        ixz="1.03446978702503E-06"
        iyy="5.18865524788486E-06"
        iyz="-6.35824592869382E-10"
        izz="6.57028614267063E-06" />
    </inertial>
    <visual>
      <origin
        xyz="0 0 0"
        rpy="0 0 0" />
      <geometry>
        <mesh
          filename="package://urdf_tutorial/meshes/TOE_foot.STL" />
      </geometry>
      <material
        name="">
        <color
          rgba="1 1 1 1" />
      </material>
    </visual>
    <collision>
      <origin rpy="0 0 0" xyz="-0.002 0 0" />
      <geometry>
        <sphere radius="0.022" />
      </geometry>
    </collision>
  </link>
  <joint
    name="RR_foot_joint"
    type="fixed">
    <origin
      xyz="0.00081567 0 -0.20051"
      rpy="0 -0.0012583 0" />
    <parent
      link="RR_calf" />
    <child
      link="RR_foot" />
  </joint>
</robot>